<?xml version="1.0" encoding="utf-8"?>
<!-- This URDF was automatically created by SolidWorks to URDF Exporter! Originally created by Stephen Brawner (brawner@gmail.com) 
     Commit Version: 1.6.0-1-g15f4949  Build Version: 1.6.7594.29634
     For more information, please see http://wiki.ros.org/sw_urdf_exporter -->
<robot
  name="leg_description">
  <link
    name="leg_base_link">
    <inertial>
      <origin
        xyz="0.02105 -0.10092 0.086245"
        rpy="0 0 0" />
      <mass
        value="0.042804" />
      <inertia
        ixx="8.9094E-06"
        ixy="-2.4796E-22"
        ixz="-1.3701E-22"
        iyy="8.9094E-06"
        iyz="7.6401E-22"
        izz="1.2371E-05" />
    </inertial>
    <visual>
      <origin
        xyz="0 0 0"
        rpy="0 0 0" />
      <geometry>
        <mesh
          filename="package://leg_description/meshes/leg_base_link.STL" />
      </geometry>
      <material
        name="">
        <color
          rgba="0.79216 0.81961 0.93333 1" />
      </material>
    </visual>
    <collision>
      <origin
        xyz="0 0 0"
        rpy="0 0 0" />
      <geometry>
        <mesh
          filename="package://leg_description/meshes/leg_base_link.STL" />
      </geometry>
    </collision>
  </link>
  <link
    name="leg_steer_link">
    <inertial>
      <origin
        xyz="-0.016905 0.0073894 0.036409"
        rpy="0 0 0" />
      <mass
        value="0.1132" />
      <inertia
        ixx="3.7579E-05"
        ixy="-6.0462E-11"
        ixz="1.9957E-11"
        iyy="3.5131E-05"
        iyz="4.3921E-07"
        izz="3.3382E-05" />
    </inertial>
    <visual>
      <origin
        xyz="0 0 0"
        rpy="0 0 0" />
      <geometry>
        <mesh
          filename="package://leg_description/meshes/leg_steer_link.STL" />
      </geometry>
      <material
        name="">
        <color
          rgba="0.79216 0.81961 0.93333 1" />
      </material>
    </visual>
    <collision>
      <origin
        xyz="0 0 0"
        rpy="0 0 0" />
      <geometry>
        <mesh
          filename="package://leg_description/meshes/leg_steer_link.STL" />
      </geometry>
    </collision>
  </link>
  <joint
    name="leg_steer_joint"
    type="revolute">
    <origin
      xyz="0.0052331 -0.12786 0.11019"
      rpy="1.5708 0 -3.1007" />
    <parent
      link="leg_base_link" />
    <child
      link="leg_steer_link" />
    <axis
      xyz="0 1 0" />
    <limit
      lower="-785398"
      upper="785398"
      effort="1"
      velocity="1" />
  </joint>
  <link
    name="leg_body_link">
    <inertial>
      <origin
        xyz="0.016905 -0.0079813 0.075121"
        rpy="0 0 0" />
      <mass
        value="0.040373" />
      <inertia
        ixx="5.5253E-05"
        ixy="3.1764E-21"
        ixz="-2.8187E-20"
        iyy="5.2295E-05"
        iyz="5.7164E-06"
        izz="4.2593E-06" />
    </inertial>
    <visual>
      <origin
        xyz="0 0 0"
        rpy="0 0 0" />
      <geometry>
        <mesh
          filename="package://leg_description/meshes/leg_body_link.STL" />
      </geometry>
      <material
        name="">
        <color
          rgba="0.79216 0.81961 0.93333 1" />
      </material>
    </visual>
    <collision>
      <origin
        xyz="0 0 0"
        rpy="0 0 0" />
      <geometry>
        <mesh
          filename="package://leg_description/meshes/leg_body_link.STL" />
      </geometry>
    </collision>
  </link>
  <joint
    name="leg_body_joint"
    type="revolute">
    <origin
      xyz="0 0.02 0.055"
      rpy="-0.62541 0 -3.1416" />
    <parent
      link="leg_steer_link" />
    <child
      link="leg_body_link" />
    <axis
      xyz="1 0 0" />
    <limit
      lower="-785398"
      upper="785398"
      effort="1"
      velocity="1" />
  </joint>
  <link
    name="knee_link">
    <inertial>
      <origin
        xyz="0.016905 -0.016174 -0.031915"
        rpy="0 0 0" />
      <mass
        value="0.022606" />
      <inertia
        ixx="5.407E-06"
        ixy="7.8435E-23"
        ixz="-2.5146E-22"
        iyy="3.6155E-06"
        iyz="-4.2278E-22"
        izz="5.6458E-06" />
    </inertial>
    <visual>
      <origin
        xyz="0 0 0"
        rpy="0 0 0" />
      <geometry>
        <mesh
          filename="package://leg_description/meshes/knee_link.STL" />
      </geometry>
      <material
        name="">
        <color
          rgba="0.79216 0.81961 0.93333 1" />
      </material>
    </visual>
    <collision>
      <origin
        xyz="0 0 0"
        rpy="0 0 0" />
      <geometry>
        <mesh
          filename="package://leg_description/meshes/knee_link.STL" />
      </geometry>
    </collision>
  </link>
  <joint
    name="knee_joint"
    type="revolute">
    <origin
      xyz="0 0 0.09"
      rpy="-2.5162 0 0" />
    <parent
      link="leg_body_link" />
    <child
      link="knee_link" />
    <axis
      xyz="1 0 0" />
    <limit
      lower="-785398"
      upper="785398"
      effort="1"
      velocity="1" />
  </joint>
  <link
    name="wheel_steer_link">
    <inertial>
      <origin
        xyz="0.015586 -0.040657 -0.032579"
        rpy="0 0 0" />
      <mass
        value="0.060967" />
      <inertia
        ixx="2.9652E-05"
        ixy="-7.8711E-22"
        ixz="-4.6755E-22"
        iyy="1.816E-05"
        iyz="-7.546E-22"
        izz="3.3325E-05" />
    </inertial>
    <visual>
      <origin
        xyz="0 0 0"
        rpy="0 0 0" />
      <geometry>
        <mesh
          filename="package://leg_description/meshes/wheel_steer_link.STL" />
      </geometry>
      <material
        name="">
        <color
          rgba="0.79216 0.81961 0.93333 1" />
      </material>
    </visual>
    <collision>
      <origin
        xyz="0 0 0"
        rpy="0 0 0" />
      <geometry>
        <mesh
          filename="package://leg_description/meshes/wheel_steer_link.STL" />
      </geometry>
    </collision>
  </link>
  <joint
    name="wheel_steer_joint"
    type="revolute">
    <origin
      xyz="0 -0.0225 0"
      rpy="0 -0.040906 0" />
    <parent
      link="knee_link" />
    <child
      link="wheel_steer_link" />
    <axis
      xyz="0 1 0" />
    <limit
      lower="-785398"
      upper="785398"
      effort="1"
      velocity="1" />
  </joint>
  <link
    name="wheel_link">
    <inertial>
      <origin
        xyz="0.015586 0 0"
        rpy="0 0 0" />
      <mass
        value="0.039231" />
      <inertia
        ixx="1.1369E-05"
        ixy="-1.5784E-38"
        ixz="4.4116E-24"
        iyy="7.2321E-06"
        iyz="3.7434E-38"
        izz="7.2321E-06" />
    </inertial>
    <visual>
      <origin
        xyz="0 0 0"
        rpy="0 0 0" />
      <geometry>
        <mesh
          filename="package://leg_description/meshes/wheel_link.STL" />
      </geometry>
      <material
        name="">
        <color
          rgba="0.79216 0.81961 0.93333 1" />
      </material>
    </visual>
    <collision>
      <origin
        xyz="0 0 0"
        rpy="0 0 0" />
      <geometry>
        <mesh
          filename="package://leg_description/meshes/wheel_link.STL" />
      </geometry>
    </collision>
  </link>
  <joint
    name="wheel_joint"
    type="continuous">
    <origin
      xyz="0 -0.061731 -0.032579"
      rpy="0 0 0" />
    <parent
      link="wheel_steer_link" />
    <child
      link="wheel_link" />
    <axis
      xyz="1 0 0" />
  </joint>
</robot>