<?xml version="1.0" encoding="utf-8"?>
<!-- This URDF was automatically created by SolidWorks to URDF Exporter! Originally created by Stephen Brawner (brawner@gmail.com) 
     Commit Version: 1.6.0-1-g15f4949  Build Version: 1.6.7594.29634
     For more information, please see http://wiki.ros.org/sw_urdf_exporter -->
<robot xmlns:xacro="http://www.ros.org/wiki/xacro">

	<xacro:macro name="swb_leg" params="name">
		  <link
		name="${name}_leg_base_link">
		<inertial>
		  <origin
			xyz="-5.3907E-35 0.011651 -4.3437E-19"
			rpy="0 0 0" />
		  <mass
			value="0.042804" />
		  <inertia
			ixx="8.9094E-06"
			ixy="-1.9704E-38"
			ixz="-2.3805E-38"
			iyy="1.2371E-05"
			iyz="5.5332E-22"
			izz="8.9094E-06" />
		</inertial>
		<visual>
		  <origin
			xyz="0 0 0"
			rpy="0 0 0" />
		  <geometry>
			<mesh
			  filename="package://leg2_description/meshes/leg_base_link.STL" />
		  </geometry>
		  <material
			name="">
			<color
			  rgba="0.79216 0.81961 0.93333 1" />
		  </material>
		</visual>
		<collision>
		  <origin
			xyz="0 0 0"
			rpy="0 0 0" />
		  <geometry>
			<mesh
			  filename="package://leg2_description/meshes/leg_base_link.STL" />
		  </geometry>
		</collision>
	  </link>
	  <link
		name="${name}_leg_steer_link">
		<inertial>
		  <origin
			xyz="-1.9141E-08 0.022985 0.010138"
			rpy="0 0 0" />
		  <mass
			value="0.1132" />
		  <inertia
			ixx="3.7579E-05"
			ixy="-6.0462E-11"
			ixz="1.9957E-11"
			iyy="3.5131E-05"
			iyz="4.3921E-07"
			izz="3.3382E-05" />
		</inertial>
		<visual>
		  <origin
			xyz="0 0 0"
			rpy="0 0 0" />
		  <geometry>
			<mesh
			  filename="package://leg2_description/meshes/leg_steer_link.STL" />
		  </geometry>
		  <material
			name="">
			<color
			  rgba="0.79216 0.81961 0.93333 1" />
		  </material>
		</visual>
		<collision>
		  <origin
			xyz="0 0 0"
			rpy="0 0 0" />
		  <geometry>
			<mesh
			  filename="package://leg2_description/meshes/leg_steer_link.STL" />
		  </geometry>
		</collision>
	  </link>
	  <joint
		name="${name}_leg_steer_joint"
		type="revolute">
		<origin
		  xyz="0 0 0.02"
		  rpy="1.5708 0 -3.1007" />
		<parent
		  link="${name}_leg_base_link" />
		<child
		  link="${name}_leg_steer_link" />
		<axis
		  xyz="0 1 0" />
		<limit
		  lower="-0.785"
		  upper="0.785"
		  effort="1"
		  velocity="1" />
	  </joint>
	  <link
		name="${name}_leg_body_link">
		<inertial>
		  <origin
			xyz="-1.43114686768087E-17 -2.08166817117217E-17 0.045"
			rpy="0 0 0" />
		  <mass
			value="0.0403727912950981" />
		  <inertia
			ixx="5.52528123330073E-05"
			ixy="2.11758236813575E-22"
			ixz="6.22039820639877E-22"
			iyy="5.29655937853257E-05"
			iyz="1.35525271560688E-20"
			izz="3.58841693331784E-06" />
		</inertial>
		<visual>
		  <origin
			xyz="0 0 0"
			rpy="0 0 0" />
		  <geometry>
			<mesh
			  filename="package://leg2_description/meshes/leg_body_link.STL" />
		  </geometry>
		  <material
			name="">
			<color
			  rgba="0.792156862745098 0.819607843137255 0.933333333333333 1" />
		  </material>
		</visual>
		<collision>
		  <origin
			xyz="0 0 0"
			rpy="0 0 0" />
		  <geometry>
			<mesh
			  filename="package://leg2_description/meshes/leg_body_link.STL" />
		  </geometry>
		</collision>
	  </link>
	  <joint
		name="${name}_leg_body_joint"
		type="revolute">
		<origin
		  xyz="0 0.02 0.055"
		  rpy="-0.50858 0 3.1416" />
		<parent
		  link="${name}_leg_steer_link" />
		<child
		  link="${name}_leg_body_link" />
		<axis
		  xyz="1 0 0" />
		<limit
		  lower="-0.785"
		  upper="0.785"
		  effort="1"
		  velocity="1" />
	  </joint>
	  <link
		name="${name}_knee_link">
		<inertial>
		  <origin
			xyz="-2.60208521396521E-18 -0.00944274905007937 0"
			rpy="0 0 0" />
		  <mass
			value="0.0226056582970217" />
		  <inertia
			ixx="5.40698778711661E-06"
			ixy="6.71955953726293E-22"
			ixz="4.36751363427999E-22"
			iyy="3.61549538401007E-06"
			iyz="-5.72788658210793E-22"
			izz="5.64577299272208E-06" />
		</inertial>
		<visual>
		  <origin
			xyz="0 0 0"
			rpy="0 0 0" />
		  <geometry>
			<mesh
			  filename="package://leg2_description/meshes/knee_link.STL" />
		  </geometry>
		  <material
			name="">
			<color
			  rgba="0.792156862745098 0.819607843137255 0.933333333333333 1" />
		  </material>
		</visual>
		<collision>
		  <origin
			xyz="0 0 0"
			rpy="0 0 0" />
		  <geometry>
			<mesh
			  filename="package://leg2_description/meshes/knee_link.STL" />
		  </geometry>
		</collision>
	  </link>
	  <joint
		name="${name}_knee_joint"
		type="revolute">
		<origin
		  xyz="0 0 0.09"
		  rpy="-2.633 0 0" />
		<parent
		  link="${name}_leg_body_link" />
		<child
		  link="${name}_knee_link" />
		<axis
		  xyz="1 0 0" />
		<limit
		  lower="-0.785"
		  upper="0.785"
		  effort="1"
		  velocity="1" />
	  </joint>
	  <link
		name${name}_wheel_steer_link">
		<inertial>
		  <origin
			xyz="0 -0.0339257637140725 0"
			rpy="0 0 0" />
		  <mass
			value="0.0609671354292965" />
		  <inertia
			ixx="2.96518139622509E-05"
			ixy="5.26616956228194E-22"
			ixz="-1.14019768539786E-22"
			iyy="1.81604420448463E-05"
			iyz="-3.75036553650419E-22"
			izz="3.33253039927572E-05" />
		</inertial>
		<visual>
		  <origin
			xyz="0 0 0"
			rpy="0 0 0" />
		  <geometry>
			<mesh
			  filename="package://leg2_description/meshes/wheel_steer_link.STL" />
		  </geometry>
		  <material
			name="">
			<color
			  rgba="0.792156862745098 0.819607843137255 0.933333333333333 1" />
		  </material>
		</visual>
		<collision>
		  <origin
			xyz="0 0 0"
			rpy="0 0 0" />
		  <geometry>
			<mesh
			  filename="package://leg2_description/meshes/wheel_steer_link.STL" />
		  </geometry>
		</collision>
	  </link>
	  <joint
		name="${name}_wheel_steer_joint"
		type="revolute">
		<origin
		  xyz="0 -0.0225 0"
		  rpy="0 -0.040906 0" />
		<parent
		  link="${name}_knee_link" />
		<child
		  link="${name}_wheel_steer_link" />
		<axis
		  xyz="0 1 0" />
		<limit
		  lower="-0.785"
		  upper="0.785"
		  effort="1"
		  velocity="1" />
	  </joint>
	  <link
		name="${name}_wheel_link">
		<inertial>
		  <origin
			xyz="-2.60208521396521E-18 1.38777878078145E-17 0"
			rpy="0 0 0" />
		  <mass
			value="0.0392305220022333" />
		  <inertia
			ixx="1.13688351684514E-05"
			ixy="-1.09278496803874E-38"
			ixz="5.73971850987445E-39"
			iyy="7.23205739455368E-06"
			iyz="-2.56179585111458E-71"
			izz="7.23205739455368E-06" />
		</inertial>
		<visual>
		  <origin
			xyz="0 0 0"
			rpy="0 0 0" />
		  <geometry>
			<mesh
			  filename="package://leg2_description/meshes/wheel_link.STL" />
		  </geometry>
		  <material
			name="">
			<color
			  rgba="0.792156862745098 0.819607843137255 0.933333333333333 1" />
		  </material>
		</visual>
		<collision>
		  <origin
			xyz="0 0 0"
			rpy="0 0 0" />
		  <geometry>
			<mesh
			  filename="package://leg2_description/meshes/wheel_link.STL" />
		  </geometry>
		</collision>
	  </link>
	  <joint
		name="${name}_wheel_joint"
		type="continuous">
		<origin
		  xyz="0 -0.055 0"
		  rpy="0 0 0" />
		<parent
		  link="${name}_wheel_steer_link" />
		<child
		  link="${name}_wheel_link" />
		<axis
		  xyz="1 0 0" />
	  </joint>
  </xacro:macro>
</robot>
